[2025-06-27T17:02:54.561+0000] {local_task_job_runner.py:120} INFO - ::group::Pre task execution logs
[2025-06-27T17:02:54.587+0000] {taskinstance.py:2076} INFO - Dependencies all met for dep_context=non-requeueable deps ti=<TaskInstance: etl_pipeline.transform manual__2025-06-27T16:57:50.939773+00:00 [queued]>
[2025-06-27T17:02:54.591+0000] {taskinstance.py:2076} INFO - Dependencies all met for dep_context=requeueable deps ti=<TaskInstance: etl_pipeline.transform manual__2025-06-27T16:57:50.939773+00:00 [queued]>
[2025-06-27T17:02:54.591+0000] {taskinstance.py:2306} INFO - Starting attempt 2 of 2
[2025-06-27T17:02:54.601+0000] {taskinstance.py:2330} INFO - Executing <Task(PythonOperator): transform> on 2025-06-27 16:57:50.939773+00:00
[2025-06-27T17:02:54.606+0000] {standard_task_runner.py:63} INFO - Started process 385 to run task
[2025-06-27T17:02:54.610+0000] {standard_task_runner.py:90} INFO - Running: ['***', 'tasks', 'run', 'etl_pipeline', 'transform', 'manual__2025-06-27T16:57:50.939773+00:00', '--job-id', '4', '--raw', '--subdir', 'DAGS_FOLDER/etl_pipeline.py', '--cfg-path', '/tmp/tmp8w063d0o']
[2025-06-27T17:02:54.614+0000] {standard_task_runner.py:91} INFO - Job 4: Subtask transform
[2025-06-27T17:02:54.630+0000] {logging_mixin.py:188} WARNING - /home/***/.local/lib/python3.10/site-packages/***/settings.py:195 DeprecationWarning: The sql_alchemy_conn option in [core] has been moved to the sql_alchemy_conn option in [database] - the old setting has been used, but please update your config.
[2025-06-27T17:02:54.662+0000] {task_command.py:426} INFO - Running <TaskInstance: etl_pipeline.transform manual__2025-06-27T16:57:50.939773+00:00 [running]> on host 8c7be4435c97
[2025-06-27T17:02:54.720+0000] {taskinstance.py:2648} INFO - Exporting env vars: AIRFLOW_CTX_DAG_OWNER='karo' AIRFLOW_CTX_DAG_ID='etl_pipeline' AIRFLOW_CTX_TASK_ID='transform' AIRFLOW_CTX_EXECUTION_DATE='2025-06-27T16:57:50.939773+00:00' AIRFLOW_CTX_TRY_NUMBER='2' AIRFLOW_CTX_DAG_RUN_ID='manual__2025-06-27T16:57:50.939773+00:00'
[2025-06-27T17:02:54.721+0000] {taskinstance.py:430} INFO - ::endgroup::
[2025-06-27T17:02:54.735+0000] {taskinstance.py:441} INFO - ::group::Post task execution logs
[2025-06-27T17:02:54.736+0000] {taskinstance.py:2905} ERROR - Task failed with exception
Traceback (most recent call last):
  File "/home/airflow/.local/lib/python3.10/site-packages/airflow/models/taskinstance.py", line 465, in _execute_task
    result = _execute_callable(context=context, **execute_callable_kwargs)
  File "/home/airflow/.local/lib/python3.10/site-packages/airflow/models/taskinstance.py", line 432, in _execute_callable
    return execute_callable(context=context, **execute_callable_kwargs)
  File "/home/airflow/.local/lib/python3.10/site-packages/airflow/models/baseoperator.py", line 400, in wrapper
    return func(self, *args, **kwargs)
  File "/home/airflow/.local/lib/python3.10/site-packages/airflow/operators/python.py", line 235, in execute
    return_value = self.execute_callable()
  File "/home/airflow/.local/lib/python3.10/site-packages/airflow/operators/python.py", line 252, in execute_callable
    return self.python_callable(*self.op_args, **self.op_kwargs)
  File "/opt/airflow/dags/etl_pipeline.py", line 18, in transform
    df = pd.read_csv(r"C:\Users\karo2\Documents\Pandas_ETL_Airflowdirty_cafe_sales.csv")
  File "/home/airflow/.local/lib/python3.10/site-packages/pandas/io/parsers/readers.py", line 948, in read_csv
    return _read(filepath_or_buffer, kwds)
  File "/home/airflow/.local/lib/python3.10/site-packages/pandas/io/parsers/readers.py", line 611, in _read
    parser = TextFileReader(filepath_or_buffer, **kwds)
  File "/home/airflow/.local/lib/python3.10/site-packages/pandas/io/parsers/readers.py", line 1448, in __init__
    self._engine = self._make_engine(f, self.engine)
  File "/home/airflow/.local/lib/python3.10/site-packages/pandas/io/parsers/readers.py", line 1705, in _make_engine
    self.handles = get_handle(
  File "/home/airflow/.local/lib/python3.10/site-packages/pandas/io/common.py", line 863, in get_handle
    handle = open(
FileNotFoundError: [Errno 2] No such file or directory: 'C:\\Users\\karo2\\Documents\\Pandas_ETL_Airflowdirty_cafe_sales.csv'
[2025-06-27T17:02:54.748+0000] {taskinstance.py:1206} INFO - Marking task as FAILED. dag_id=etl_pipeline, task_id=transform, run_id=manual__2025-06-27T16:57:50.939773+00:00, execution_date=20250627T165750, start_date=20250627T170254, end_date=20250627T170254
[2025-06-27T17:02:54.756+0000] {standard_task_runner.py:110} ERROR - Failed to execute job 4 for task transform ([Errno 2] No such file or directory: 'C:\\Users\\karo2\\Documents\\Pandas_ETL_Airflowdirty_cafe_sales.csv'; 385)
[2025-06-27T17:02:54.782+0000] {local_task_job_runner.py:240} INFO - Task exited with return code 1
[2025-06-27T17:02:54.799+0000] {taskinstance.py:3498} INFO - 0 downstream tasks scheduled from follow-on schedule check
[2025-06-27T17:02:54.803+0000] {local_task_job_runner.py:222} INFO - ::endgroup::
