[2025-06-30T21:15:39.831+0000] {local_task_job_runner.py:120} INFO - ::group::Pre task execution logs
[2025-06-30T21:15:39.858+0000] {taskinstance.py:2076} INFO - Dependencies all met for dep_context=non-requeueable deps ti=<TaskInstance: etl_pipeline.load manual__2025-06-30T21:15:37.116629+00:00 [queued]>
[2025-06-30T21:15:39.866+0000] {taskinstance.py:2076} INFO - Dependencies all met for dep_context=requeueable deps ti=<TaskInstance: etl_pipeline.load manual__2025-06-30T21:15:37.116629+00:00 [queued]>
[2025-06-30T21:15:39.868+0000] {taskinstance.py:2306} INFO - Starting attempt 1 of 2
[2025-06-30T21:15:39.878+0000] {taskinstance.py:2330} INFO - Executing <Task(PythonOperator): load> on 2025-06-30 21:15:37.116629+00:00
[2025-06-30T21:15:39.885+0000] {standard_task_runner.py:63} INFO - Started process 197 to run task
[2025-06-30T21:15:39.889+0000] {standard_task_runner.py:90} INFO - Running: ['***', 'tasks', 'run', 'etl_pipeline', 'load', 'manual__2025-06-30T21:15:37.116629+00:00', '--job-id', '5', '--raw', '--subdir', 'DAGS_FOLDER/etl_pipeline.py', '--cfg-path', '/tmp/tmpaizr7vnj']
[2025-06-30T21:15:39.892+0000] {standard_task_runner.py:91} INFO - Job 5: Subtask load
[2025-06-30T21:15:39.911+0000] {logging_mixin.py:188} WARNING - /home/***/.local/lib/python3.10/site-packages/***/settings.py:195 DeprecationWarning: The sql_alchemy_conn option in [core] has been moved to the sql_alchemy_conn option in [database] - the old setting has been used, but please update your config.
[2025-06-30T21:15:39.956+0000] {task_command.py:426} INFO - Running <TaskInstance: etl_pipeline.load manual__2025-06-30T21:15:37.116629+00:00 [running]> on host b363f1e8b1b5
[2025-06-30T21:15:40.029+0000] {taskinstance.py:2648} INFO - Exporting env vars: AIRFLOW_CTX_DAG_OWNER='karo' AIRFLOW_CTX_DAG_ID='etl_pipeline' AIRFLOW_CTX_TASK_ID='load' AIRFLOW_CTX_EXECUTION_DATE='2025-06-30T21:15:37.116629+00:00' AIRFLOW_CTX_TRY_NUMBER='1' AIRFLOW_CTX_DAG_RUN_ID='manual__2025-06-30T21:15:37.116629+00:00'
[2025-06-30T21:15:40.030+0000] {taskinstance.py:430} INFO - ::endgroup::
[2025-06-30T21:15:40.084+0000] {taskinstance.py:441} INFO - ::group::Post task execution logs
[2025-06-30T21:15:40.085+0000] {taskinstance.py:2905} ERROR - Task failed with exception
Traceback (most recent call last):
  File "/home/airflow/.local/lib/python3.10/site-packages/airflow/models/taskinstance.py", line 465, in _execute_task
    result = _execute_callable(context=context, **execute_callable_kwargs)
  File "/home/airflow/.local/lib/python3.10/site-packages/airflow/models/taskinstance.py", line 432, in _execute_callable
    return execute_callable(context=context, **execute_callable_kwargs)
  File "/home/airflow/.local/lib/python3.10/site-packages/airflow/models/baseoperator.py", line 400, in wrapper
    return func(self, *args, **kwargs)
  File "/home/airflow/.local/lib/python3.10/site-packages/airflow/operators/python.py", line 235, in execute
    return_value = self.execute_callable()
  File "/home/airflow/.local/lib/python3.10/site-packages/airflow/operators/python.py", line 252, in execute_callable
    return self.python_callable(*self.op_args, **self.op_kwargs)
  File "/opt/airflow/dags/etl_pipeline.py", line 91, in load
    fact_sales = df[[
  File "/home/airflow/.local/lib/python3.10/site-packages/pandas/core/frame.py", line 3899, in __getitem__
    indexer = self.columns._get_indexer_strict(key, "columns")[1]
  File "/home/airflow/.local/lib/python3.10/site-packages/pandas/core/indexes/base.py", line 6115, in _get_indexer_strict
    self._raise_if_missing(keyarr, indexer, axis_name)
  File "/home/airflow/.local/lib/python3.10/site-packages/pandas/core/indexes/base.py", line 6179, in _raise_if_missing
    raise KeyError(f"{not_found} not in index")
KeyError: "['Transaction_ID'] not in index"
[2025-06-30T21:15:40.098+0000] {taskinstance.py:1206} INFO - Marking task as UP_FOR_RETRY. dag_id=etl_pipeline, task_id=load, run_id=manual__2025-06-30T21:15:37.116629+00:00, execution_date=20250630T211537, start_date=20250630T211539, end_date=20250630T211540
[2025-06-30T21:15:40.108+0000] {standard_task_runner.py:110} ERROR - Failed to execute job 5 for task load ("['Transaction_ID'] not in index"; 197)
[2025-06-30T21:15:40.142+0000] {local_task_job_runner.py:240} INFO - Task exited with return code 1
[2025-06-30T21:15:40.156+0000] {taskinstance.py:3498} INFO - 0 downstream tasks scheduled from follow-on schedule check
[2025-06-30T21:15:40.159+0000] {local_task_job_runner.py:222} INFO - ::endgroup::
